<?xml version="1.0" ?>
<!-- =================================================================================== -->
<!-- |    This document was autogenerated by xacro from right_sim.xacro                | -->
<!-- |    EDITING THIS FILE BY HAND IS NOT RECOMMENDED                                 | -->
<!-- =================================================================================== -->
<robot name="hyuspa_v2">
  <!--  <collision>
    <origin rpy="${colvis_rpy}" xyz="${colvis_xyz}" />
    <geometry>
      <mesh filename="${meshfile}" scale="${meshscale}"/>
    </geometry>
  </collision>-->
  <!-- END - Include -->
  <link name="world"/>
  <joint name="world_base" type="fixed">
    <parent link="world"/>
    <child link="Arm_Link_base"/>
    <origin rpy="0 0 0" xyz="0 0 0"/>
  </joint>
  <link name="Arm_Link_base"/>
  <joint name="Arm_Joint_base_joint" type="fixed">
    <parent link="Arm_Link_base"/>
    <child link="SPA_Base_Link"/>
    <origin rpy="0 0 0" xyz="0 0 0"/>
  </joint>
  <link name="SPA_Base_Link">
    <inertial>
      <mass value="14.299"/>
      <origin rpy="0 0 0" xyz="0.0 -0.01869 0.75176"/>
      <inertia ixx="4.7569" ixy="3.5447e-06" ixz="1.3257e-05" iyy="4.7075" iyz="0.21788" izz="0.16593"/>
    </inertial>
    <visual>
      <origin rpy="0 0 0" xyz="0 0 0"/>
      <geometry>
        <mesh filename="package://hyuspa_v2_description/meshes/hyuspa_v2/SPA_Base_Link.STL" scale="1 1 1"/>
      </geometry>
      <material name="light_black"/>
    </visual>
  </link>
  <joint name="Arm_Joint_1" type="revolute">
    <axis xyz="0 1 0"/>
    <limit effort="50" lower="-3.09" upper="1.11" velocity="2.4"/>
    <origin rpy="0 0 0" xyz="0 -0.3107 1.567"/>
    <parent link="SPA_Base_Link"/>
    <child link="SPA_Link_01"/>
    <dynamics damping="0.0" friction="0.7"/>
  </joint>
  <transmission name="trans_Arm_Joint_1">
    <type>transmission_interface/SimpleTransmission</type>
    <joint name="Arm_Joint_1">
      <hardwareInterface>hardware_interface/EffortJointInterface</hardwareInterface>
    </joint>
    <actuator name="motor_Arm_Joint_1">
      <hardwareInterface>hardware_interface/EffortJointInterface</hardwareInterface>
      <mechanicalReduction>1</mechanicalReduction>
    </actuator>
  </transmission>
  <link name="SPA_Link_01">
    <inertial>
      <mass value="0.19006"/>
      <origin rpy="0 0 0" xyz="0.00255 -0.04684 0.00039303"/>
      <inertia ixx="0.0001285" ixy="6.9599e-06" ixz="3.35e-07" iyy="0.00013782" iyz="-1.5817e-06" izz="0.00017651"/>
    </inertial>
    <visual>
      <origin rpy="0 0 0" xyz="0 0 0"/>
      <geometry>
        <mesh filename="package://hyuspa_v2_description/meshes/hyuspa_v2/SPA_Link_01.STL" scale="1 1 1"/>
      </geometry>
      <material name="light_black"/>
    </visual>
  </link>
  <joint name="Arm_Joint_2" type="revolute">
    <axis xyz="1 0 0"/>
    <limit effort="50" lower="-1.57" upper="1.9" velocity="2.4"/>
    <origin rpy="0 0 0" xyz="0 -0.054 0"/>
    <parent link="SPA_Link_01"/>
    <child link="SPA_Link_02"/>
    <dynamics damping="0.0" friction="0.7"/>
  </joint>
  <transmission name="trans_Arm_Joint_2">
    <type>transmission_interface/SimpleTransmission</type>
    <joint name="Arm_Joint_2">
      <hardwareInterface>hardware_interface/EffortJointInterface</hardwareInterface>
    </joint>
    <actuator name="motor_Arm_Joint_2">
      <hardwareInterface>hardware_interface/EffortJointInterface</hardwareInterface>
      <mechanicalReduction>1</mechanicalReduction>
    </actuator>
  </transmission>
  <link name="SPA_Link_02">
    <inertial>
      <mass value="1.42162"/>
      <origin rpy="0 0 0" xyz="0.00093 -0.00217 -0.08254"/>
      <inertia ixx="0.00368181349" ixy="-0.00018327606" ixz="-2.68131e-06" iyy="0.00104405709" iyz="3.34569e-06" izz="0.00406650369"/>
    </inertial>
    <visual>
      <origin rpy="0 0 0" xyz="0 0 0"/>
      <geometry>
        <mesh filename="package://hyuspa_v2_description/meshes/hyuspa_v2/SPA_Link_02.STL" scale="1 1 1"/>
      </geometry>
      <material name="light_black"/>
    </visual>
  </link>
  <joint name="Arm_Joint_3" type="revolute">
    <axis xyz="0 0 1"/>
    <limit effort="50" lower="-1.09" upper="1.34" velocity="2.4"/>
    <origin rpy="0 0 0" xyz="0 0 -0.1458"/>
    <parent link="SPA_Link_02"/>
    <child link="SPA_Link_03"/>
    <dynamics damping="0.0" friction="0.7"/>
  </joint>
  <transmission name="trans_Arm_Joint_3">
    <type>transmission_interface/SimpleTransmission</type>
    <joint name="Arm_Joint_3">
      <hardwareInterface>hardware_interface/EffortJointInterface</hardwareInterface>
    </joint>
    <actuator name="motor_Arm_Joint_3">
      <hardwareInterface>hardware_interface/EffortJointInterface</hardwareInterface>
      <mechanicalReduction>1</mechanicalReduction>
    </actuator>
  </transmission>
  <link name="SPA_Link_03">
    <inertial>
      <mass value="0.2435"/>
      <origin rpy="0 0 0" xyz="-0.00092 0.00049 -0.11495"/>
      <inertia ixx="0.00068284" ixy="-8.5183e-06" ixz="-4.7514e-07" iyy="0.00022011" iyz="8.8649e-06" izz="0.00063402"/>
    </inertial>
    <visual>
      <origin rpy="0 0 0" xyz="0 0 0"/>
      <geometry>
        <mesh filename="package://hyuspa_v2_description/meshes/hyuspa_v2/SPA_Link_03.STL" scale="1 1 1"/>
      </geometry>
      <material name="light_black"/>
    </visual>
  </link>
  <joint name="Arm_Joint_4" type="revolute">
    <axis xyz="0 1 0"/>
    <limit effort="50" lower="-2.48" upper="0.156" velocity="2.4"/>
    <origin rpy="0 0 0" xyz="0 0 -0.1542"/>
    <parent link="SPA_Link_03"/>
    <child link="SPA_Link_04"/>
    <dynamics damping="0.0" friction="0.7"/>
  </joint>
  <transmission name="trans_Arm_Joint_4">
    <type>transmission_interface/SimpleTransmission</type>
    <joint name="Arm_Joint_4">
      <hardwareInterface>hardware_interface/EffortJointInterface</hardwareInterface>
    </joint>
    <actuator name="motor_Arm_Joint_4">
      <hardwareInterface>hardware_interface/EffortJointInterface</hardwareInterface>
      <mechanicalReduction>1</mechanicalReduction>
    </actuator>
  </transmission>
  <link name="SPA_Link_04">
    <inertial>
      <mass value="1.1894"/>
      <origin rpy="0 0 0" xyz="-0.00204 -0.00034 -0.08047"/>
      <inertia ixx="0.00324613078" ixy="-2.02519e-06" ixz="1.1493e-07" iyy="0.00054844144" iyz="0.00023013877" izz="0.00324899669"/>
    </inertial>
    <visual>
      <origin rpy="0 0 0" xyz="0 0 0"/>
      <geometry>
        <mesh filename="package://hyuspa_v2_description/meshes/hyuspa_v2/SPA_Link_04.STL" scale="1 1 1"/>
      </geometry>
      <material name="light_black"/>
    </visual>
  </link>
  <joint name="Arm_Joint_5" type="revolute">
    <axis xyz="0 0 1"/>
    <limit effort="50" lower="-1.392" upper="1.41" velocity="2.4"/>
    <origin rpy="0 0 0" xyz="0 0 -0.1458"/>
    <parent link="SPA_Link_04"/>
    <child link="SPA_Link_05"/>
    <dynamics damping="0.0" friction="0.7"/>
  </joint>
  <transmission name="trans_Arm_Joint_5">
    <type>transmission_interface/SimpleTransmission</type>
    <joint name="Arm_Joint_5">
      <hardwareInterface>hardware_interface/EffortJointInterface</hardwareInterface>
    </joint>
    <actuator name="motor_Arm_Joint_5">
      <hardwareInterface>hardware_interface/EffortJointInterface</hardwareInterface>
      <mechanicalReduction>1</mechanicalReduction>
    </actuator>
  </transmission>
  <link name="SPA_Link_05">
    <inertial>
      <mass value="0.36826"/>
      <origin rpy="0 0 0" xyz="0.00000229 -0.00084 -0.11414"/>
      <inertia ixx="0.0029078647" ixy="8.047904e-05" ixz="-1.276791e-05" iyy="0.00028211059" iyz="-0.00014451678" izz="0.0030636283"/>
    </inertial>
    <visual>
      <origin rpy="0 0 0" xyz="0 0 0"/>
      <geometry>
        <mesh filename="package://hyuspa_v2_description/meshes/hyuspa_v2/SPA_Link_05.STL" scale="1 1 1"/>
      </geometry>
      <material name="light_black"/>
    </visual>
  </link>
  <joint name="Arm_Joint_6" type="revolute">
    <axis xyz="1 0 0"/>
    <limit effort="50" lower="-1.41" upper="1.392" velocity="2.4"/>
    <origin rpy="0 0 0" xyz="0 0 -0.1542"/>
    <parent link="SPA_Link_05"/>
    <child link="SPA_Link_06"/>
    <dynamics damping="0.0" friction="0.7"/>
  </joint>
  <transmission name="trans_Arm_Joint_6">
    <type>transmission_interface/SimpleTransmission</type>
    <joint name="Arm_Joint_6">
      <hardwareInterface>hardware_interface/EffortJointInterface</hardwareInterface>
    </joint>
    <actuator name="motor_Arm_Joint_6">
      <hardwareInterface>hardware_interface/EffortJointInterface</hardwareInterface>
      <mechanicalReduction>1</mechanicalReduction>
    </actuator>
  </transmission>
  <link name="SPA_Link_06">
    <inertial>
      <mass value="0.36826"/>
      <origin rpy="0 0 0" xyz="0.00222 0.00091 -0.00853"/>
      <inertia ixx="0.0029078647" ixy="8.047904e-05" ixz="-1.276791e-05" iyy="0.00028211059" iyz="-0.00014451678" izz="0.0030636283"/>
    </inertial>
    <visual>
      <origin rpy="0 0 0" xyz="0 0 0"/>
      <geometry>
        <mesh filename="package://hyuspa_v2_description/meshes/hyuspa_v2/SPA_Link_06.STL" scale="1 1 1"/>
      </geometry>
      <material name="light_black"/>
    </visual>
  </link>
  <!-- END - Robot description -->
  <gazebo>
    <plugin filename="libgazebo_ros_p3d.so" name="p3d_base_controller">
      <alwaysOn>true</alwaysOn>
      <updateRate>1000.0</updateRate>
      <bodyName>SPA_Link_05</bodyName>
      <topicName>ground_truth/state</topicName>
      <gaussianNoise>0</gaussianNoise>
      <frameName>world</frameName>
      <xyzOffsets>0 0 0</xyzOffsets>
      <rpyOffsets>0 0 0</rpyOffsets>
    </plugin>
  </gazebo>
  <gazebo>
    <plugin filename="libgazebo_ros_control.so" name="gazebo_ros_control">
      <robotSimType>gazebo_ros_control/DefaultRobotHWSim</robotSimType>
      <legacyModeNS>true</legacyModeNS>
      <controlPeriod>0.001</controlPeriod>
      <robotNamespace>/hyuspa_v2</robotNamespace>
    </plugin>
  </gazebo>
</robot>

